<?xml version="1.0" ?>
<sdf version="1.5">
  <model name="rubbish_robot">
    <link name="chassis">
      <pose>0 0 0.16 0 0 0</pose>
      <inertial>
        <mass>5.67</mass>
        <inertia>
          <ixx>0.07</ixx>
          <iyy>0.08</iyy>
          <izz>0.10</izz>
          <ixy>0</ixy>
          <ixz>0</ixz>
          <iyz>0</iyz>
        </inertia>
      </inertial>
      <collision name="collision">
        <geometry>
          <box>
            <size>0.445 0.277 0.17</size>
          </box>
        </geometry>
      </collision>
      <collision name="castor_collision">
        <pose>-0.200 0 -0.12 0 0 0</pose>
        <geometry>
          <sphere>
            <radius>0.04</radius>
          </sphere>
        </geometry>
        <surface>
          <friction>
            <ode>
              <mu>0</mu>
              <mu2>0</mu2>
              <slip1>1.0</slip1>
              <slip2>1.0</slip2>
            </ode>
          </friction>
        </surface>
      </collision>
      <visual name="visual">
        <pose>0 0 0.04 0 0 0</pose>
        <geometry>
          <mesh>
            <uri>model://pioneer2dx/meshes/chassis.dae</uri>
          </mesh>
        </geometry>
      </visual>
      <visual name="castor_visual">
        <pose>-0.200 0 -0.12 0 0 0</pose>
        <geometry>
          <sphere>
            <radius>0.04</radius>
          </sphere>
        </geometry>
        <material>
          <script>
            <uri>file://media/materials/scripts/gazebo.material</uri>
            <name>Gazebo/FlatBlack</name>
          </script>
        </material>
      </visual>
    </link>
    <link name="right_wheel">
      <pose>0.1 -.17 0.11 0 1.5707 1.5707</pose>
      <inertial>
        <mass>1.5</mass>
        <inertia>
          <ixx>0.0051</ixx>
          <iyy>0.0051</iyy>
          <izz>0.0090</izz>
          <ixy>0</ixy>
          <ixz>0</ixz>
          <iyz>0</iyz>
        </inertia>
      </inertial>
      <collision name="collision">
        <geometry>
          <cylinder>
            <radius>0.11</radius>
            <length>0.05</length>
          </cylinder>
        </geometry>
        <surface>
          <friction>
            <ode>
              <mu>100000.0</mu>
              <mu2>100000.0</mu2>
              <slip1>0.0</slip1>
              <slip2>0.0</slip2>
            </ode>
          </friction>
        </surface>
      </collision>
      <visual name="visual">
        <geometry>
          <cylinder>
            <radius>0.11</radius>
            <length>0.05</length>
          </cylinder>
        </geometry>
        <material>
          <script>
            <uri>file://media/materials/scripts/gazebo.material</uri>
            <name>Gazebo/FlatBlack</name>
          </script>
        </material>
      </visual>
    </link>
    <link name="left_wheel">
      <pose>0.1 .17 0.11 0 1.5707 1.5707</pose>
      <inertial>
        <mass>1.5</mass>
        <inertia>
          <ixx>0.0051</ixx>
          <iyy>0.0051</iyy>
          <izz>0.0090</izz>
          <ixy>0</ixy>
          <ixz>0</ixz>
          <iyz>0</iyz>
        </inertia>
      </inertial>
      <collision name="collision">
        <geometry>
          <cylinder>
            <radius>0.11</radius>
            <length>0.05</length>
          </cylinder>
        </geometry>
        <surface>
          <friction>
            <ode>
              <mu>100000.0</mu>
              <mu2>100000.0</mu2>
              <slip1>0.0</slip1>
              <slip2>0.0</slip2>
            </ode>
          </friction>
        </surface>
      </collision>
      <visual name="visual">
        <geometry>
          <cylinder>
            <radius>0.11</radius>
            <length>0.05</length>
          </cylinder>
        </geometry>
        <material>
          <script>
            <uri>file://media/materials/scripts/gazebo.material</uri>
            <name>Gazebo/FlatBlack</name>
          </script>
        </material>
      </visual>
    </link>
    <joint type="revolute" name="left_wheel_hinge">
      <pose>0 0 -0.03 0 0 0</pose>
      <child>left_wheel</child>
      <parent>chassis</parent>
      <axis>
        <xyz>0 1 0</xyz>
        <use_parent_model_frame>true</use_parent_model_frame>
      </axis>
    </joint>
    <joint type="revolute" name="right_wheel_hinge">
      <pose>0 0 0.03 0 0 0</pose>
      <child>right_wheel</child>
      <parent>chassis</parent>
      <axis>
        <xyz>0 1 0</xyz>
        <use_parent_model_frame>true</use_parent_model_frame>
      </axis>
    </joint>
<plugin name='differential_drive_controller' filename='libgazebo_ros_diff_drive.so'>
      <alwaysOn>true</alwaysOn>
      <updateRate>100</updateRate>
      <leftJoint>base_right_wheel_joint</leftJoint>
      <rightJoint>base_left_wheel_joint</rightJoint>
      <wheelSeparation>0.34</wheelSeparation>
      <wheelDiameter>0.22</wheelDiameter>
      <torque>5</torque>
      <commandTopic>cmd_vel</commandTopic>
      <odometryTopic>odom</odometryTopic>
      <odometryFrame>odom</odometryFrame>
      <robotBaseFrame>base_link</robotBaseFrame>
      <robotNamespace>/</robotNamespace>
      <publishWheelTF>true</publishWheelTF>
      <publishWheelJointState>true</publishWheelJointState>
      <wheelAcceleration>0</wheelAcceleration>
      <wheelTorque>5</wheelTorque>
      <rosDebugLevel>na</rosDebugLevel>
      <legacyMode>true</legacyMode>
      <publishTf>1</publishTf>
    </plugin>
<link name="lidar">
      <pose>0 0 0.28 0 0 0</pose>
      <inertial>
        <mass>1.5</mass>
        <inertia>
          <ixx>0.0051</ixx>
          <iyy>0.0051</iyy>
          <izz>0.0090</izz>
          <ixy>0</ixy>
          <ixz>0</ixz>
          <iyz>0</iyz>
        </inertia>
      </inertial>
      <collision name="collision-base">
        <pose>0 0 -0.0145 0 0 0</pose>
        <geometry>
          <box>
            <size>0.05 0.05 0.041</size>
          </box>
        </geometry>
      </collision>
      <collision name="collision-top">
        <pose>0 0 0.0205 0 0 0</pose>
        <geometry>
          <cylinder>
            <radius>0.021</radius>
            <length>0.029</length>
          </cylinder>
        </geometry>
      </collision>
      <sensor name="laser" type="ray">
        <pose>0.01 0 0.0175 0 -0 0</pose>
        <ray>
          <scan>
            <horizontal>
              <samples>720</samples>
              <resolution>1</resolution>
              <min_angle>-3.14</min_angle>
              <max_angle>3.14</max_angle>
            </horizontal>
          </scan>
          <range>
            <min>0.1</min>
            <max>10</max>
            <resolution>0.01</resolution>
          </range>
        </ray>
        <plugin name="laser" filename="libRayPlugin.so" />
        <always_on>1</always_on>
        <update_rate>30</update_rate>
        <visualize>true</visualize>
      </sensor>
      <visual name="visual">
        <geometry>
          <cylinder>
            <radius>0.10</radius>
            <length>0.05</length>
          </cylinder>
        </geometry>
        <material>
          <script>
            <uri>file://media/materials/scripts/gazebo.material</uri>
            <name>Gazebo/FlatBlack</name>
          </script>
        </material>
      </visual>
    </link>
    <joint type="fixed" name="lidar_joint">
      <pose>0 0 0.0 0 0 0</pose>
      <child>lidar</child>
      <parent>chassis</parent>
      <axis>
        <xyz>0 0 0</xyz>
        <use_parent_model_frame>true</use_parent_model_frame>
      </axis>
    </joint> 


<link name="camera">
	<pose>0.165895 0.001365 0.163495 0 0 0</pose>
      <inertial>
        <mass>0.1</mass>
        <inertia>
          <ixx>0.000166667</ixx>
          <iyy>0.000166667</iyy>
          <izz>0.000166667</izz>
        </inertia>
      </inertial>
      <collision name="collision">
        <geometry>
          <box>
            <size>0.1 0.1 0.1</size>
          </box>
        </geometry>
      </collision>
      <visual name="visual">
        <geometry>
          <box>
            <size>0.1 0.1 0.1</size>
          </box>
        </geometry>
      </visual>
      <sensor name="camera" type="camera">
        <camera>
          <horizontal_fov>1.047</horizontal_fov>
          <image>
            <width>320</width>
            <height>240</height>
          </image>
          <clip>
            <near>0.1</near>
            <far>100</far>
          </clip>
        </camera>
        <always_on>1</always_on>
        <update_rate>30</update_rate>
        <visualize>true</visualize>
      </sensor>
    </link>
    
   <joint type="fixed" name="camera_joint">
      <pose>0 0 3 0 0 0</pose>
      <child>camera</child>
      <parent>chassis</parent>
      <axis>
        <xyz>0 0 3</xyz>
        <use_parent_model_frame>true</use_parent_model_frame>
      </axis>
    </joint> 
<plugin name='gazebo_ros_control' filename='libgazebo_ros_control.so'>
      <robotNamespace>/p3dx</robotNamespace>
    </plugin>
    <plugin name='p3d_base_controller' filename='libgazebo_ros_p3d.so'>
      <alwaysOn>true</alwaysOn>
      <updateRate>100.0</updateRate>
      <bodyName>base_link</bodyName>
      <topicName>p3dx/base_pose_ground_truth</topicName>
      <gaussianNoise>0.01</gaussianNoise>
      <frameName>map</frameName>
      <xyzOffsets>0 0 0</xyzOffsets>
      <rpyOffsets>0 0 0</rpyOffsets>
      <robotNamespace>/</robotNamespace>
    </plugin>
  

  </model>
</sdf>

